Workbook
Name Cars: Misc!$A$4:$A$114

Sheet Steps Calculator
A1: INPUT | E1: OUTPUT - SUSPENSION
A2: Car selection | B2: Dodge Challenger SRT | C2: Wheelbase, m | E2: Springs stiffness | F2: Front springs | G2: Rear springs
A3: Engine selection | B3: Dodge Challenger SRT | C3: {=VLOOKUP($B$2, Misc!$A$4:$AF$114, 5, 0)} -> 2.934 | F3: ='Suspension calculator'!D4 -> 173.44062 | G3: ='Suspension calculator'!E4 -> 135.36205
A4: Weight, kg | B4: 1788 | C4: Front track width | E4: Dampers | F4: Front dampers | G4: Rear dampers
A5: Front weight distribution, % | B5: 56 | C5: {=VLOOKUP($B$2, Misc!$A$4:$AF$114, 6, 0)} -> 1.63 | E5: Bump | F5: ='Suspension calculator'!D16 -> 12274.637 | G5: ='Suspension calculator'!E16 -> 9579.7632
A6: Front wheel offset, cm | B6: 3 | C6: Rear track width | E6: Fast bump | F6: ='Suspension calculator'!D17 -> 6137.3184 | G6: ='Suspension calculator'!E17 -> 4789.8816
A7: Rear wheel offset, cm | B7: -3 | C7: {=VLOOKUP($B$2, Misc!$A$4:$AF$114, 7, 0)} -> 1.62 | E7: Rebound | F7: ='Suspension calculator'!D18 -> 27617.933 | G7: ='Suspension calculator'!E18 -> 21554.467
A8: Desired ride frequency (3 - 5) | B8: 3 | E8: Fast rebound | F8: ='Suspension calculator'!D19 -> 13808.966 | G8: ='Suspension calculator'!E19 -> 10777.234
A9: Desired roll gradient (0.02 - 0.7) | B9: 0.05 | C9: Real Y engine offset
A10: Wheel diameter, inches | B10: 20 | C10: {=(VLOOKUP($B$2, Misc!$A$4:$AF$114, 22, 0))+(VLOOKUP($B$3, Misc!$A$4:$AF$114, 31, 0))} -> 0.568 | D10: 1 | E10: Anti-roll bars | F10: FARB, kNm | G10: RARB, kNm
A11: Profile, % | B11: 40 | C11: Real Z engine offset | F11: ='Suspension calculator'!A38 -> -130.52599 | G11: ='Suspension calculator'!B38 -> -91.456983
A12: Tire width, mm | B12: 345 | C12: {=(VLOOKUP($B$2, Misc!$A$4:$AF$114, 23, 0))+(VLOOKUP($B$3, Misc!$A$4:$AF$114, 32, 0))} -> 2.021
A13: CoG height, inches | B13: 20 | E13: Weight transfer on acceleration, kg | G13: =B13*2.54/100/C3*B4*'Suspension calculator'!A43 -> 186.52476
A14: Acceleration, 0-100 km/h, s | B14: 4.7 | E14: Front weight distribution on acceleration | G14: ='Gearbox calculator'!R74 -> 0.45567966
A15: Max speed @ 118 m radius | B15: 140 | E15: Max longitudinal acceleration, g | G15: ='Gearbox calculator'!Q70 -> 0.60251155
A16: Drivetrain | B16: RWD/AWD | E16: Max lateral acceleration, g | G16: ='Suspension calculator'!B43 -> 1.3064739
A18: INPUT - TRANSMISSION
A19: Torque, Nm | B19: RPM | C19: Gear | D19: Ratio
A20: 410.8 | B20: 358 | C20: 1st | D20: 2.76
A21: 434.2 | B21: 626 | C21: 2nd | D21: 2
A22: 465.2 | B22: 893 | C22: 3rd | D22: 1.5
A23: 514.8 | B23: 1161 | C23: 4th | D23: 1.15
A24: 578.1 | B24: 1428 | C24: 5th | D24: 1
A25: 646.8 | B25: 1696 | C25: 6th | D25: 0.9
A26: 720 | B26: 1963 | C26: 7th
A27: 800.1 | B27: 2231 | C27: 8th
A28: 888.8 | B28: 2498 | C28: Final drive | D28: 3
A29: 977 | B29: 2766
A30: 1050.9 | B30: 3033
A31: 1098.3 | B31: 3301
A32: 1125.5 | B32: 3568
A33: 1149.3 | B33: 3836
A34: 1171.5 | B34: 4103
A35: 1194.4 | B35: 4371
A36: 1215.3 | B36: 4638
A37: 1230.8 | B37: 4906
A38: 1239.1 | B38: 5173
A39: 1239.1 | B39: 5441
A40: 1221.2 | B40: 5708
... A49: 839.6 | B49: 8116

Sheet 3, 4 & 8 speed gearboxes
A1: Gearboxes
A2: Car | B2: A90 | D2: A90C | F2: RS6 | H2: SRT8 | J2: C7 | L2: M5 | N2: Vantage | P2: X5M
A3: FD | B3: 1.56 | C3: 3.72 | D3: 1.56 | E3: 3.72 | F3: 1.6 | G3: 3.82 | H3: 1.6 | I3: 3.82 | J3: 1.25 | K3: 2.98 | L3: 2.16 | M3: 5.15 | N3: 2.19 | O3: 5.21 | P3: 2.16 | Q3: 5.15
A4: 1 | B4: 3.57 | C4: 7.35 | D4: 3.57 | E4: 7.35 | F4: 3.2 | G4: 6.59 | H4: 3.2 | I4: 6.59 | J4: 3.1 | K4: 6.38 | L4: 3.4 | M4: 7 | N4: 3.2 | O4: 6.59 | P4: 3.4 | Q4: 7
A5: 2 | B5: 2.28 | C5: 4.7 | D5: 2.28 | E5: 4.7 | F5: 2.14 | G5: 4.4 | H5: 2.14 | I5: 4.4 | J5: 2.02 | K5: 4.16 | L5: 2.18 | M5: 4.48 | N5: 2.14 | O5: 4.4 | P5: 2.18 | Q5: 4.48
A6: 3 | B6: 1.48 | C6: 3.04 | D6: 1.48 | E6: 3.04 | F6: 1.43 | G6: 2.95 | H6: 1.43 | I6: 2.94 | J6: 1.41 | K6: 2.91 | L6: 1.46 | M6: 3 | N6: 1.43 | O6: 2.95 | P6: 1.46 | Q6: 3
A7: 4 | B7: 1.17 | C7: 2.41 | D7: 1.17 | E7: 2.41 | F7: 1.14 | G7: 2.34 | H7: 1.14 | I7: 2.34 | J7: 1.15 | K7: 2.37 | L7: 1.17 | M7: 2.41 | N7: 1.14 | O7: 2.34 | P7: 1.17 | Q7: 2.41
A8: 5 | B8: 0.9 | C8: 1.85 | D8: 0.9 | E8: 1.85 | F8: 0.87 | G8: 1.79 | H8: 0.88 | I8: 1.81 | J8: 0.86 | K8: 1.78 | L8: 0.89 | M8: 1.83 | N8: 0.87 | O8: 1.79 | P8: 0.89 | Q8: 1.83
A9: 6 | B9: 0.78 | C9: 1.61 | D9: 0.68 | E9: 1.4 | F9: 0.68 | G9: 1.4 | H9: 0.68 | I9: 1.4 | J9: 0.68 | K9: 1.4 | L9: 0.68 | M9: 1.4 | N9: 0.68 | O9: 1.4 | P9: 0.68 | Q9: 1.4
A10: 7 | B10: 0.6 | C10: 1.23 | D10: 0.56 | E10: 1.15 | F10: 0.57 | G10: 1.18 | H10: 0.57 | I10: 1.18 | J10: 0.58 | K10: 1.2 | L10: 0.56 | M10: 1.15 | N10: 0.57 | O10: 1.18 | P10: 0.56 | Q10: 1.15
A11: 8 | B11: 0.54 | C11: 1.11 | D11: 0.44 | E11: 0.9 | F11: 0.46 | G11: 0.94 | H11: 0.46 | I11: 0.94 | J11: 0.44 | K11: 0.91 | L11: 0.44 | M11: 0.9 | N11: 0.49 | O11: 1.01 | P11: 0.44 | Q11: 0.9
A12: R | B12: 2.52 | C12: 5.19 | D12: 2.52 | E12: 5.19 | F12: 2.26 | G12: 4.65 | H12: 2.24 | I12: 4.62 | J12: 2.6 | K12: 5.35 | L12: 2.37 | M12: 4.87 | N12: 2.26 | O12: 4.65 | P12: 2.37 | Q12: 4.87
P13: YOUR AD COULD BE HERE!
A19: Gearboxes
A20: Car | B20: 190 | D20: Van | F20: Firebird | H20: Charger RT | J20: VAZ 2108 | L20: Camaro 2nd gen
A21: FD | B21: 1.6 | C21: 3.81 | D21: 2.13 | E21: 5.08 | F21: 1.42 | G21: 3.38 | H21: 1.68 | I21: 4 | J21: 2.15 | K21: 5.12 | L21: 1.84 | M21: 4.4
A22: 1 | B22: 2.89 | C22: 5.95 | D22: 1.99 | E22: 4.09 | F22: 1.5 | G22: 3.08 | H22: 1.8 | I22: 3.71 | J22: 2.31 | K22: 4.76 | L22: 1.69 | M22: 3.47
A23: 2 | B23: 1.64 | C23: 3.37 | D23: 1.06 | E23: 2.18 | F23: 1.12 | G23: 2.3 | H23: 1.31 | I23: 2.7 | J23: 1.33 | K23: 2.73 | L23: 1.01 | M23: 2.07
A24: 3 | B24: 1.01 | C24: 2.09 | D24: 0.68 | E24: 1.4 | F24: 0.87 | G24: 1.79 | H24: 0.95 | I24: 1.95 | J24: 0.92 | K24: 1.9 | L24: 0.68 | M24: 1.4
A25: 4 | B25: 0.68 | C25: 1.4 | D25: 0.48 | E25: 0.98 | F25: 0.68 | G25: 1.4 | H25: 0.68 | I25: 1.4 | J25: 0.64 | K25: 1.32 | L25: - | M25: -
A26: R | B26: 3.86 | C26: 7.94 | D26: 1.62 | E26: 3.33 | F26: 1.54 | G26: 3.18 | H26: 1.5 | I26: 3.08 | J26: 2.4 | K26: 4.94 | L26: 1.41 | M26: 2.91

Sheet Suspension calculator
A1: Springs & Dampers
A3: Weight of the car, W, kg | C3: Wheel weight, kg | D3: Front spring stiffness, Ks | E3: Rear spring stiffness, Ks
A4: ='Steps Calculator'!B4 -> 1788 | C4: 12 | D4: =4*3.14^2*A13^2*A10/1000 -> 173.44062 | E4: =4*3.14^2*A13^2*B10/1000 -> 135.36205
A5: Front weight, %, kg | B5: Rear weight, %, kg | D5: K = 4 x π^2 x f^2 x m
A6: ='Steps Calculator'!B5/100 -> 0.56 | B6: =1-A6 -> 0.44
A7: =A4*A6 -> 1001.28 | B7: =A4*B6 -> 786.72 | D7: Crit damping force front | E7: Crit damping force rear
D8: =2*SQRT(D4*1000*A10) -> 18411.955 | E8: =2*SQRT(E4*1000*B10) -> 14369.645
A9: Front sprung mass, m | B9: Rear sprung mass, m | D9: Ccrit = 2 x SQRT(K x m)
A10: =A7/2-C4 -> 488.64 | B10: =B7/2-C4 -> 381.36
D11: Damping force front, C | E11: Damping force rear, C
A12: Ride frequency, f | B12: Damping ratio, ζ | D12: =D8*B13 -> 18411.955 | E12: =E8*B13 -> 14369.645
A13: ='Steps Calculator'!B8 -> 3 | B13: 1 | D13: C = Ccrit x ζ
A15: f values for racecars | B15: ζ values for racecars | D15: Front dampers | E15: Rear dampers
A16: 3,0 - 5,0+ Hz | B16: 0,65+ | C16: Bump C x 2/3 | D16: =D12*2/3 -> 12274.637 | E16: =E12*2/3 -> 9579.7632
C17: Fast bump C x 1/3 | D17: =D12*1/3 -> 6137.3184 | E17: =E12*1/3 -> 4789.8816
A18: Acceleration time, s | C18: Rebound C x 3/2 | D18: =D12*3/2 -> 27617.933 | E18: =E12*3/2 -> 21554.467
A19: ='Steps Calculator'!B14 -> 4.7 | C19: Fast rebound C x 3/4 | D19: =D12*3/4 -> 13808.966 | E19: =E12*3/4 -> 10777.234
A21: Anti-roll bars
A23: Roll center to CoG, H, m | B23: Front track width, t, m | C23: Rear track width, t, m | D23: φ/Ay, desired roll gradient | E23: Magic number, Nmag
A24: 0.3 | B24: ='Steps Calculator'!C5+'Steps Calculator'!B6/100 -> 1.66 | C24: ='Steps Calculator'!C7+'Steps Calculator'!B7/100 -> 1.59 | D24: ='Steps Calculator'!B9 -> 0.05 | E24: =A6*1.05*100 -> 58.8
B25: =(B24+C24)/2 -> 1.625
A27: Front wheel rate, Kw | B27: Rear wheel rate, Kw | C27: Tire rate, Kt, N | D27: KφDES, desired roll rate
A28: =D4*1000 -> 173440.62 | B28: =E4*1000 -> 135362.05 | C28: =35*9.80665*1000 -> 343232.75 | D28: =A4*A24/D24 -> 10728
A29: =(A28+B28)/2 -> 154401.34
A31: Total roll rate KφA, Nm/deg | C31: KφDES = W x H / (φ/Ay) KφA = π / 180 x (KφDES x Kt x (t^2 / 2)) / ((Kt x (t^2 / 2) x π / 180 - KφDES) - (π x Kw x (t^2 / 2) / 180) KφFA = KφA x Nmag / 100 KφRA = KφA x (100 - Nmag) / 100 ARB = KφF(R)A * π / (180 * t^2)
A32: =(3.14/180)*(D28*C28*(B25^2/2))/(C28*(B25^2/2)*3.14/180-D28)-(3.14*A29*B25^2/2)/180 -> -33602.318
A34: FARB KφFA, Nm/deg | B34: RARB KφRA, Nm/deg
A35: =A32*E24/100 -> -19758.163 | B35: =A32*(100-E24)/100 -> -13844.155
A37: FARB, kNm | B37: RARB, kNm
A38: =A35*3.14/(180*B25^2) -> -130.52599 | B38: =B35*3.14/(180*B25^2) -> -91.456983
A40: Acceleration
A42: Long acceleration calc, g | B42: Lat acceleration calc, g
A43: =(27.78-0)/A19/9.81 -> 0.60251155 | B43: =('Steps Calculator'!B15*0.277778)^2/(118*9.81) -> 1.3064739
A44: a = (vf - vs) / dt | B44: Aa = V^2 / R x g

Sheet Gearbox calculator
A1: Torque | B1: HP | C1: RPM | D1: 1st | E1: 2nd | F1: 3rd | G1: 4th | H1: 5th | I1: 6th | J1: 7th | K1: 8th | L1: FD
D2: ='Steps Calculator'!D20 -> 2.76 | E2: ='Steps Calculator'!D21 -> 2 | F2: ='Steps Calculator'!D22 -> 1.5 | G2: ='Steps Calculator'!D23 -> 1.15 | H2: ='Steps Calculator'!D24 -> 1 | I2: ='Steps Calculator'!D25 -> 0.9 | J2: ='Steps Calculator'!D26 | K2: ='Steps Calculator'!D27 | L2: ='Steps Calculator'!D28 -> 3
D3: =D2*$L$2 -> 8.28 | E3: =E2*$L$2 -> 6 | F3: =F2*$L$2 -> 4.5 | G3: =G2*$L$2 -> 3.45 | H3: =H2*$L$2 -> 3 | I3: =I2*$L$2 -> 2.7 | J3: =J2*$L$2 -> 0 | K3: =K2*$L$2 -> 0
A4: ='Steps Calculator'!A20 -> 410.8 | B4: =A4*C4/9549*1.34102 -> 20.653365 | C4: ='Steps Calculator'!B20 -> 358 | D4: =A4*$D$3 -> 3401.424 | E4: =A4*$E$3 -> 2464.8 | F4: =A4*$F$3 -> 1848.6 | G4: =A4*$G$3 -> 1417.26 | H4: =A4*$H$3 -> 1232.4 | I4: =A4*$I$3 -> 1109.16 | J4: =A4*$J$3 -> 0 | K4: =A4*$K$3 -> 0
A5: ='Steps Calculator'!A21 -> 434.2 | B5: =A5*C5/9549*1.34102 -> 38.171701 | C5: ='Steps Calculator'!B21 -> 626 | D5: =A5*$D$3 -> 3595.176 | E5: =A5*$E$3 -> 2605.2 | F5: =A5*$F$3 -> 1953.9 | G5: =A5*$G$3 -> 1497.99 | H5: =A5*$H$3 -> 1302.6 | I5: =A5*$I$3 -> 1172.34 | J5: =A5*$J$3 -> 0 | K5: =A5*$K$3 -> 0
A6: ='Steps Calculator'!A22 -> 465.2 | B6: =A6*C6/9549*1.34102 -> 58.340282 | C6: ='Steps Calculator'!B22 -> 893 | D6: =A6*$D$3 -> 3851.856 | E6: =A6*$E$3 -> 2791.2 | F6: =A6*$F$3 -> 2093.4 | G6: =A6*$G$3 -> 1604.94 | H6: =A6*$H$3 -> 1395.6 | I6: =A6*$I$3 -> 1256.04 | J6: =A6*$J$3 -> 0 | K6: =A6*$K$3 -> 0
A7: ='Steps Calculator'!A23 -> 514.8 | B7: =A7*C7/9549*1.34102 -> 83.935971 | C7: ='Steps Calculator'!B23 -> 1161 | D7: =A7*$D$3 -> 4262.544 | E7: =A7*$E$3 -> 3088.8 | F7: =A7*$F$3 -> 2316.6 | G7: =A7*$G$3 -> 1776.06 | H7: =A7*$H$3 -> 1544.4 | I7: =A7*$I$3 -> 1389.96 | J7: =A7*$J$3 -> 0 | K7: =A7*$K$3 -> 0
A8: ='Steps Calculator'!A24 -> 578.1 | B8: =A8*C8/9549*1.34102 -> 115.93339 | C8: ='Steps Calculator'!B24 -> 1428 | D8: =A8*$D$3 -> 4786.668 | E8: =A8*$E$3 -> 3468.6 | F8: =A8*$F$3 -> 2601.45 | G8: =A8*$G$3 -> 1994.445 | H8: =A8*$H$3 -> 1734.3 | I8: =A8*$I$3 -> 1560.87 | J8: =A8*$J$3 -> 0 | K8: =A8*$K$3 -> 0
A9: ='Steps Calculator'!A25 -> 646.8 | B9: =A9*C9/9549*1.34102 -> 154.05409 | C9: ='Steps Calculator'!B25 -> 1696 | D9: =A9*$D$3 -> 5355.504 | E9: =A9*$E$3 -> 3880.8 | F9: =A9*$F$3 -> 2910.6 | G9: =A9*$G$3 -> 2231.46 | H9: =A9*$H$3 -> 1940.4 | I9: =A9*$I$3 -> 1746.36 | J9: =A9*$J$3 -> 0 | K9: =A9*$K$3 -> 0
A10: ='Steps Calculator'!A26 -> 720 | B10: =A10*C10/9549*1.34102 -> 198.48613 | C10: ='Steps Calculator'!B26 -> 1963 | D10: =A10*$D$3 -> 5961.6 | E10: =A10*$E$3 -> 4320 | F10: =A10*$F$3 -> 3240 | G10: =A10*$G$3 -> 2484 | H10: =A10*$H$3 -> 2160 | I10: =A10*$I$3 -> 1944 | J10: =A10*$J$3 -> 0 | K10: =A10*$K$3 -> 0
A11: ='Steps Calculator'!A27 -> 800.1 | B11: =A11*C11/9549*1.34102 -> 250.68088 | C11: ='Steps Calculator'!B27 -> 2231 | D11: =A11*$D$3 -> 6624.828 | E11: =A11*$E$3 -> 4800.6 | F11: =A11*$F$3 -> 3600.45 | G11: =A11*$G$3 -> 2760.345 | H11: =A11*$H$3 -> 2400.3 | I11: =A11*$I$3 -> 2160.27 | J11: =A11*$J$3 -> 0 | K11: =A11*$K$3 -> 0
A12: ='Steps Calculator'!A28 -> 888.8 | B12: =A12*C12/9549*1.34102 -> 311.79837 | C12: ='Steps Calculator'!B28 -> 2498 | D12: =A12*$D$3 -> 7359.264 | E12: =A12*$E$3 -> 5332.8 | F12: =A12*$F$3 -> 3999.6 | G12: =A12*$G$3 -> 3066.36 | H12: =A12*$H$3 -> 2666.4 | I12: =A12*$I$3 -> 2399.76 | J12: =A12*$J$3 -> 0 | K12: =A12*$K$3 -> 0
A13: ='Steps Calculator'!A29 -> 977 | B13: =A13*C13/9549*1.34102 -> 379.51077 | C13: ='Steps Calculator'!B29 -> 2766 | D13: =A13*$D$3 -> 8089.56 | E13: =A13*$E$3 -> 5862 | F13: =A13*$F$3 -> 4396.5 | G13: =A13*$G$3 -> 3370.65 | H13: =A13*$H$3 -> 2931 | I13: =A13*$I$3 -> 2637.9 | J13: =A13*$J$3 -> 0 | K13: =A13*$K$3 -> 0
A14: ='Steps Calculator'!A30 -> 1050.9 | B14: =A14*C14/9549*1.34102 -> 447.62173 | C14: ='Steps Calculator'!B30 -> 3033 | D14: =A14*$D$3 -> 8701.452 | E14: =A14*$E$3 -> 6305.4 | F14: =A14*$F$3 -> 4729.05 | G14: =A14*$G$3 -> 3625.605 | H14: =A14*$H$3 -> 3152.7 | I14: =A14*$I$3 -> 2837.43 | J14: =A14*$J$3 -> 0 | K14: =A14*$K$3 -> 0
A15: ='Steps Calculator'!A31 -> 1098.3 | B15: =A15*C15/9549*1.34102 -> 509.1478 | C15: ='Steps Calculator'!B31 -> 3301 | D15: =A15*$D$3 -> 9093.924 | E15: =A15*$E$3 -> 6589.8 | F15: =A15*$F$3 -> 4942.35 | G15: =A15*$G$3 -> 3789.135 | H15: =A15*$H$3 -> 3294.9 | I15: =A15*$I$3 -> 2965.41 | J15: =A15*$J$3 -> 0 | K15: =A15*$K$3 -> 0
... A33: ='Steps Calculator'!A49 -> 839.6 | B33: =A33*C33/9549*1.34102 -> 956.95569 | C33: ='Steps Calculator'!B49 -> 8116 | D33: =A33*$D$3 -> 6951.888 | E33: =A33*$E$3 -> 5037.6 | F33: =A33*$F$3 -> 3778.2 | G33: =A33*$G$3 -> 2896.62 | H33: =A33*$H$3 -> 2518.8 | I33: =A33*$I$3 -> 2266.92 | J33: =A33*$J$3 -> 0 | K33: =A33*$K$3 -> 0
A35: RPM * 60 * Circumference / 63360 / Drive | H35: Tire width | I35: Profile % | J35: 1 inch to mm | K35: Rim D | L35: π | M35: Circumference
H36: ='Steps Calculator'!B12 -> 345 | I36: ='Steps Calculator'!B11/100 -> 0.4 | J36: 25.4 | K36: ='Steps Calculator'!B10 -> 20 | L36: 3.14 | M36: =(H36*I36/J36*2+K36)*L36 -> 96.919685
A37: Peak HP RPM | B37: =IFERROR(__xludf.DUMMYFUNCTION("FILTER(C4:C33,B4:B33=MAX(B4:B33))"),6778.0) -> 6778 | H37: Wheel radius | I37: =(H36*I36/J36*2+K36)*2.54/2/100 -> 0.392
A39: RPM | B39: Speed kph | C39: 1 TQ | D39: 2 TQ | E39: 3 TQ | F39: 4 TQ | G39: 5 TQ | H39: 6 TQ | I39: 7 TQ | J39: 8 TQ | K39: Traction curve | L39: Traction limit
A40: =C4 -> 358 | B40: =A40*60*$M$36/63360/$D$3*1.60934 -> 6.3862891 | C40: =D4 -> 3401.424 | K40: =IF(A40=$B$37,C40,"") | L40: =IF('Steps Calculator'!B16="RWD/AWD",O77,P77) -> 6871.4727
A41: =C5 -> 626 | B41: =A41*60*$M$36/63360/$D$3*1.60934 -> 11.167086 | C41: =D5 -> 3595.176 | K41: =IF(A41=$B$37,C41,"")
A42: =C6 -> 893 | B42: =A42*60*$M$36/63360/$D$3*1.60934 -> 15.930045 | C42: =D6 -> 3851.856 | K42: =IF(A42=$B$37,C42,"")
A43: =C7 -> 1161 | B43: =A43*60*$M$36/63360/$D$3*1.60934 -> 20.710842 | C43: =D7 -> 4262.544 | K43: =IF(A43=$B$37,C43,"")
A44: =C8 -> 1428 | B44: =A44*60*$M$36/63360/$D$3*1.60934 -> 25.473801 | C44: =D8 -> 4786.668 | K44: =IF(A44=$B$37,C44,"")
A45: =C9 -> 1696 | B45: =A45*60*$M$36/63360/$D$3*1.60934 -> 30.254598 | C45: =D9 -> 5355.504 | K45: =IF(A45=$B$37,C45,"")
A46: =C10 -> 1963 | B46: =A46*60*$M$36/63360/$D$3*1.60934 -> 35.017557 | C46: =D10 -> 5961.6 | K46: =IF(A46=$B$37,C46,"")
A47: =C11 -> 2231 | B47: =A47*60*$M$36/63360/$D$3*1.60934 -> 39.798354 | C47: =D11 -> 6624.828 | K47: =IF(A47=$B$37,C47,"")
A48: =C12 -> 2498 | B48: =A48*60*$M$36/63360/$D$3*1.60934 -> 44.561313 | C48: =D12 -> 7359.264 | K48: =IF(A48=$B$37,C48,"")
A49: =C13 -> 2766 | B49: =A49*60*$M$36/63360/$D$3*1.60934 -> 49.34211 | C49: =D13 -> 8089.56 | K49: =IF(A49=$B$37,C49,"")
A50: =C14 -> 3033 | B50: =A50*60*$M$36/63360/$D$3*1.60934 -> 54.105069 | C50: =D14 -> 8701.452 | K50: =IF(A50=$B$37,C50,"")
A51: =C15 -> 3301 | B51: =A51*60*$M$36/63360/$D$3*1.60934 -> 58.885866 | C51: =D15 -> 9093.924 | K51: =IF(A51=$B$37,C51,"")
A52: =C16 -> 3568 | B52: =A52*60*$M$36/63360/$D$3*1.60934 -> 63.648825 | C52: =D16 -> 9319.14 | K52: =IF(A52=$B$37,C52,"")
... A64: =C28 -> 6778 | B64: =A64*60*$M$36/63360/$D$3*1.60934 -> 120.91136 | C64: =D28 -> 8851.32 | K64: =IF(A64=$B$37,C64,"") -> 8851.32
A65: =C29 -> 7046 | B65: =A65*60*$M$36/63360/$D$3*1.60934 -> 125.69216 | C65: =D29 -> 8511.012 | K65: =IF(A65=$B$37,C65,"") | O65: CoG height in | P65: CoG height m | Q65: Wheelbase m | R65: Mass kg, (m) | S65: Weight bias (%) | T65: Wheel (R) | U65: Fric. coef. (µ) | V65: Street | W65: 1.12
A66: =C30 -> 7313 | B66: =A66*60*$M$36/63360/$D$3*1.60934 -> 130.45512 | C66: =D30 -> 8180.64 | K66: =IF(A66=$B$37,C66,"") | O66: ='Steps Calculator'!B13 -> 20 | P66: =O66*2.54/100 -> 0.508 | Q66: ='Steps Calculator'!C3 -> 2.934 | R66: ='Steps Calculator'!B4 -> 1788 | S66: ='Steps Calculator'!B5/100 -> 0.56 | T66: =I37 -> 0.392 | U66: =W71*W70 -> 1.836 | V66: Street+ | W66: 1.16
A67: =C31 -> 7581 | B67: =A67*60*$M$36/63360/$D$3*1.60934 -> 135.23591 | C67: =D31 -> 7826.256 | K67: =IF(A67=$B$37,C67,"") | V67: Sport | W67: 1.4
A68: =C32 -> 7849 | B68: =A68*60*$M$36/63360/$D$3*1.60934 -> 140.01671 | C68: =D32 -> 7413.912 | K68: =IF(A68=$B$37,C68,"") | V68: Sport+ | W68: 1.45
A69: =C33 -> 8116 | B69: =A69*60*$M$36/63360/$D$3*1.60934 -> 144.77967 | C69: =D33 -> 6951.888 | K69: =IF(A69=$B$37,C69,"") | O69: Front weight | P69: Rear weight | Q69: Acceleration, g | V69: Racing | W69: 1.7
A70: =C4 -> 358 | B70: =A40*60*$M$36/63360/$E$3*1.60934 -> 8.8130789 | D70: =E4 -> 2464.8 | K70: =IF(A70=$B$37,D70,"") | O70: =R66*S66 -> 1001.28 | P70: =R66-O70 -> 786.72 | Q70: ='Suspension calculator'!A43 -> 0.60251155 | V70: Racing+ | W70: 1.7
...

Sheet Misc
A1: Car | B1: Wheelbase, track width (meters) | I1: Transmission | L1: Body | X1: Engine
L2: Stock | O2: Body Stage 1/2 | R2: Body Stage 3/4 | U2: Position offset X | V2: Position offset Y | W2: Position offset Z | X2: Power HP | Y2: Mass Kg | Z2: Turbo Press. | AA2: Curve fall @ RPM | AB2: Rev limiter | AC2: Inertia ratio | AD2: Position offset X | AE2: Position offset Y | AF2: Position offset Z
B3: Height | C3: F axle offset | D3: R axle offset | E3: Wheelbase | F3: F track width | G3: R track width | H3: AV track width | I3: Gears | J3: Shift time | K3: Weight | L3: CX | M3: SX | N3: Drag | O3: CX | P3: SX | Q3: Drag | R3: CX | S3: SX | T3: Drag
A4: Nissan 300ZX (Z32) Convertible | B4: 0.4 | C4: 1.347 | D4: -1.297 | E4: =C4+(-1*D4) -> 2.644 | F4: 1.56 | G4: 1.6 | H4: =AVERAGE(F4:G4) -> 1.58 | I4: 5 | J4: 0.5 | K4: 50 | L4: 0.3 | M4: 2 | N4: =L4*M4 -> 0.6 | O4: 0.29 | P4: 2 | Q4: =O4*P4 -> 0.58 | R4: 0.28 | S4: 2 | T4: =R4*S4 -> 0.56 | U4: 0 | V4: 0.385 | W4: 1.4 | X4: 221 | Y4: 220 | Z4: 0.62 | AA4: 7000 | AB4: 6800 | AC4: 1 | AD4: 0 | AE4: 0.1 | AF4: 0.2
A5: BMW E39 M5 Touring | B5: 0.3 | C5: 1.52 | D5: -1.32 | E5: =C5+(-1*D5) -> 2.84 | F5: 1.32 | G5: 1.32 | H5: =AVERAGE(F5:G5) -> 1.32 | I5: 6 | J5: 0.3 | K5: 50 | L5: 0.3 | M5: 2 | N5: =L5*M5 -> 0.6 | O5: 0.29 | P5: 2 | Q5: =O5*P5 -> 0.58 | R5: 0.28 | S5: 2 | T5: =R5*S5 -> 0.56 | U5: 0 | V5: 0.34 | W5: 2.1 | X5: 285 | Y5: 208 | Z5: NA | AA5: 7000 | AB5: 7000 | AC5: 1 | AD5: 0 | AE5: 0.14 | AF5: 0.34
A6: BMW M3 E92 Cabriolet | B6: 0.32 | C6: 1.5 | D6: -1.253 | E6: =C6+(-1*D6) -> 2.753 | F6: 1.54 | G6: 1.53 | H6: =AVERAGE(F6:G6) -> 1.535 | I6: 6 | J6: 0.5 | K6: 50 | L6: 0.3 | M6: 2 | N6: =L6*M6 -> 0.6 | O6: 0.29 | P6: 2 | Q6: =O6*P6 -> 0.58 | R6: 0.28 | S6: 2 | T6: =R6*S6 -> 0.56 | U6: 0 | V6: 0.372 | W6: 1.411 | X6: 342 | Y6: 135 | Z6: 0.65 | AA6: 7000 | AB6: 6800 | AC6: 1 | AD6: 0 | AE6: 0 | AF6: 0
A7: Toyota Supra A90 Roadster | B7: 0.38 | C7: 1.23 | D7: -1.26 | E7: =C7+(-1*D7) -> 2.49 | F7: 1.58 | G7: 1.56 | H7: =AVERAGE(F7:G7) -> 1.57 | I7: 8 | J7: 0.5 | K7: 50 | L7: 0.3 | M7: 2 | N7: =L7*M7 -> 0.6 | O7: 0.29 | P7: 2 | Q7: =O7*P7 -> 0.58 | R7: 0.28 | S7: 2 | T7: =R7*S7 -> 0.56 | U7: 0 | V7: 0.458 | W7: 1.169 | X7: 327 | Y7: 140 | Z7: 0.75 | AA7: 7000 | AB7: 7000 | AC7: 1 | AD7: 0 | AE7: 0.08 | AF7: 0.18
A8: Ford Mustang S650 | B8: 0.46 | C8: 1.46 | D8: -1.26 | E8: =C8+(-1*D8) -> 2.72 | F8: 1.27 | G8: 1.27 | H8: =AVERAGE(F8:G8) -> 1.27 | I8: 6 | J8: 0.3 | K8: 50 | L8: 0.3 | M8: 2 | N8: =L8*M8 -> 0.6 | O8: 0.29 | P8: 2 | Q8: =O8*P8 -> 0.58 | R8: 0.28 | S8: 2 | T8: =R8*S8 -> 0.56 | U8: 0 | V8: 0.592 | W8: 1.477 | X8: 399 | Y8: 186 | Z8: 0.82 | AA8: 7000 | AB8: 7500 | AC8: 1 | AD8: 0 | AE8: 0.14 | AF8: 0.4
A9: BMW i8 | B9: 0.413 | C9: 1.386 | D9: -1.42 | E9: =C9+(-1*D9) -> 2.806 | F9: 1.7 | G9: 1.72 | H9: =AVERAGE(F9:G9) -> 1.71 | I9: 6 | J9: 0.3 | K9: 50 | L9: 0.3 | M9: 2 | N9: =L9*M9 -> 0.6 | O9: 0.29 | P9: 2 | Q9: =O9*P9 -> 0.58 | R9: 0.28 | S9: 2 | T9: =R9*S9 -> 0.56 | U9: 0 | V9: 0.607 | W9: -0.957 | X9: 331 | Y9: 210 | Z9: 0.65 | AA9: 7000 | AB9: 6500 | AC9: 1 | AD9: 0 | AE9: -0.06 | AF9: 0.03
A10: Nissan 400Z | B10: 0.46 | C10: 1.269 | D10: -1.281 | E10: =C10+(-1*D10) -> 2.55 | F10: 1.57 | G10: 1.53 | H10: =AVERAGE(F10:G10) -> 1.55 | I10: 6 | J10: 0.3 | K10: 50 | L10: 0.3 | M10: 2 | N10: =L10*M10 -> 0.6 | O10: 0.29 | P10: 2 | Q10: =O10*P10 -> 0.58 | R10: 0.28 | S10: 2 | T10: =R10*S10 -> 0.56 | U10: 0 | V10: 0.528 | W10: 1.286 | X10: 400 | Y10: 240 | Z10: 1.03 | AA10: 7000 | AB10: 6800 | AC10: 1 | AD10: 0 | AE10: 0.1 | AF10: 0.2
A11: Lamborghini Huracan | B11: 0.39 | C11: 1.21 | D11: -1.41 | E11: =C11+(-1*D11) -> 2.62 | F11: 1.668 | G11: 1.62 | H11: =AVERAGE(F11:G11) -> 1.644 | I11: 7 | J11: 0.3 | K11: 50 | L11: 0.3 | M11: 2 | N11: =L11*M11 -> 0.6 | O11: 0.29 | P11: 2 | Q11: =O11*P11 -> 0.58 | R11: 0.28 | S11: 2 | T11: =R11*S11 -> 0.56 | U11: 0 | V11: 0.65 | W11: -1.182 | X11: 401 | Y11: 250 | Z11: 1.35 | AA11: 7000 | AB11: 8000 | AC11: 1 | AD11: 0 | AE11: 0.17 | AF11: 0.42
A12: Mercedes-Benz G55 AMG W463 | B12: 0.29 | C12: 1.5 | D12: -1.27 | E12: =C12+(-1*D12) -> 2.77 | F12: 1.24 | G12: 1.24 | H12: =AVERAGE(F12:G12) -> 1.24 | I12: 7 | J12: 0.3 | K12: 50 | L12: 0.3 | M12: 2 | N12: =L12*M12 -> 0.6 | O12: 0.29 | P12: 2 | Q12: =O12*P12 -> 0.58 | R12: 0.28 | S12: 2 | T12: =R12*S12 -> 0.56 | U12: 0 | V12: 0.484 | W12: 1.495 | X12: 544 | Y12: 220 | Z12: 1 | AA12: 7000 | AB12: 6500 | AC12: 1 | AD12: 0 | AE12: 0.18 | AF12: 0.52
A13: Nissan Silvia S15 Drift | B13: =B57 -> 0.255 | C13: =C57 -> 1.275 | D13: =D57 -> -1.23 | E13: =C13+(-1*D13) -> 2.505 | F13: =F57 -> 1.46 | G13: =G57 -> 1.46 | H13: =AVERAGE(F13:G13) -> 1.46 | I13: =I57 -> 6 | J13: =J57 -> 0.5 | K13: 50 | L13: 0.3 | M13: 2 | N13: =L13*M13 -> 0.6 | O13: 0.29 | P13: 2 | Q13: =O13*P13 -> 0.58 | R13: 0.28 | S13: 2 | T13: =R13*S13 -> 0.56 | U13: 0 | V13: =V57 -> 0.376 | W13: =W57 -> 1.328 | X13: =X57 -> 229 | Y13: =Y57 -> 180 | Z13: =Z57 -> 0.6 | AA13: =AA57 -> 7000 | AB13: =AB57 -> 7500 | AC13: =AC57 -> 1 | AD13: 0 | AE13: -0.04 | AF13: 0.1
A14: Mercedes-Benz 190 W201 Sunset | B14: =B29 -> 0.36 | C14: =C29 -> 1.24 | D14: =D29 -> -1.43 | E14: =C14+(-1*D14) -> 2.67 | F14: =F29 -> 1.42 | G14: =G29 -> 1.42 | H14: =AVERAGE(F14:G14) -> 1.42 | I14: =I29 -> 4 | J14: =J29 -> 0.3 | K14: 50 | L14: 0.3 | M14: 2 | N14: =L14*M14 -> 0.6 | O14: 0.29 | P14: 2 | Q14: =O14*P14 -> 0.58 | R14: 0.28 | S14: 2 | T14: =R14*S14 -> 0.56 | U14: 0 | V14: =V29 -> 0.46 | W14: =W29 -> 1.255 | X14: =X29 -> 165 | Y14: =Y29 -> 170 | Z14: NA | AA14: =AA29 -> 7000 | AB14: =AB29 -> 6600 | AC14: =AC29 -> 1 | AD14: 0 | AE14: -0.03 | AF14: 0.15
A15: Tesla Model S Plaid | B15: 0.46 | C15: 1.5 | D15: -1.45 | E15: =C15+(-1*D15) -> 2.95 | F15: 1.26 | G15: 1.28 | H15: =AVERAGE(F15:G15) -> 1.27 | I15: 2 | J15: 0 | K15: 50 | L15: 0.3 | M15: 2 | N15: =L15*M15 -> 0.6 | O15: 0.29 | P15: 2 | Q15: =O15*P15 -> 0.58 | R15: 0.28 | S15: 2 | T15: =R15*S15 -> 0.56 | U15: 0 | V15: 0.352 | W15: -0.414 | X15: 666 | Y15: 300 | Z15: NA | AA15: 7000 | AB15: 10000 | AC15: 0.5 | AD15: 0 | AE15: 0 | AF15: 0
A16: Porsche 911 GT3 992 | B16: 0.5 | C16: 1.295 | D16: -1.156 | E16: =C16+(-1*D16) -> 2.451 | F16: 1.27 | G16: 1.35 | H16: =AVERAGE(F16:G16) -> 1.31 | I16: 6 | J16: 0.3 | K16: 50 | L16: 0.3 | M16: 2 | N16: =L16*M16 -> 0.6 | O16: 0.29 | P16: 2 | Q16: =O16*P16 -> 0.58 | R16: 0.28 | S16: 2 | T16: =R16*S16 -> 0.56 | U16: 0 | V16: 0.62 | W16: -1.338 | X16: 419 | Y16: 230 | Z16: 1 | AA16: 7000 | AB16: 9000 | AC16: 1 | AD16: 0 | AE16: 0.13 | AF16: 0.3
A17: McLaren 720S | B17: 0.43 | C17: 1.3 | D17: -1.435 | E17: =C17+(-1*D17) -> 2.735 | F17: 1.22 | G17: 1.24 | H17: =AVERAGE(F17:G17) -> 1.23 | I17: 7 | J17: 0.3 | K17: 50 | L17: 0.3 | M17: 2 | N17: =L17*M17 -> 0.6 | O17: 0.29 | P17: 2 | Q17: =O17*P17 -> 0.58 | R17: 0.28 | S17: 2 | T17: =R17*S17 -> 0.56 | U17: 0 | V17: 0.576 | W17: -1.133 | X17: 442 | Y17: 170 | Z17: 1.3 | AA17: 7000 | AB17: 8500 | AC17: 1 | AD17: 0 | AE17: 0.13 | AF17: 0.3
A18: Lamborghini Aventador S | B18: 0.46 | C18: 1.235 | D18: -1.435 | E18: =C18+(-1*D18) -> 2.67 | F18: 1.22 | G18: 1.2 | H18: =AVERAGE(F18:G18) -> 1.21 | I18: 7 | J18: 0.3 | K18: 50 | L18: 0.3 | M18: 2 | N18: =L18*M18 -> 0.6 | O18: 0.29 | P18: 2 | Q18: =O18*P18 -> 0.58 | R18: 0.28 | S18: 2 | T18: =R18*S18 -> 0.56 | U18: 0 | V18: 0.568 | W18: -1.047 | X18: 514 | Y18: 235 | Z18: NA | AA18: 7000 | AB18: 8500 | AC18: 1 | AD18: 0 | AE18: 0.18 | AF18: 0.52
A19: Nissan 180SX Drift | B19: =B34 -> 0.319 | C19: =C34 -> 1.285 | D19: =D34 -> -1.2 | E19: =C19+(-1*D19) -> 2.485 | F19: =F34 -> 1.46 | G19: =G34 -> 1.46 | H19: =AVERAGE(F19:G19) -> 1.46 | I19: =I34 -> 5 | J19: =J34 -> 0.5 | K19: 50 | L19: 0.3 | M19: 2 | N19: =L19*M19 -> 0.6 | O19: 0.29 | P19: 2 | Q19: =O19*P19 -> 0.58 | R19: 0.28 | S19: 2 | T19: =R19*S19 -> 0.56 | U19: 0 | V19: =V34 -> 0.427 | W19: =W34 -> 1.35 | X19: =X34 -> 185 | Y19: =Y34 -> 268 | Z19: =Z34 -> 0.6 | AA19: =AA34 -> 7000 | AB19: =AB34 -> 7200 | AC19: =AC34 -> 1 | AD19: 0 | AE19: -0.04 | AF19: 0.08
A20: Mazda RX-7 FD3S Drift | B20: =B84 -> 0.43 | C20: =C84 -> 1.305 | D20: =D84 -> -1.114 | E20: =C20+(-1*D20) -> 2.419 | F20: =F84 -> 1.45 | G20: =G84 -> 1.45 | H20: =AVERAGE(F20:G20) -> 1.45 | I20: =I84 -> 5 | J20: =J84 -> 0.5 | K20: 50 | L20: 0.3 | M20: 2 | N20: =L20*M20 -> 0.6 | O20: 0.29 | P20: 2 | Q20: =O20*P20 -> 0.58 | R20: 0.28 | S20: 2 | T20: =R20*S20 -> 0.56 | U20: 0 | V20: =V84 -> 0.46 | W20: =W84 -> 1.286 | X20: =X84 -> 280 | Y20: =Y84 -> 120 | Z20: =Z84 -> 0.41 | AA20: =AA84 -> 7000 | AB20: =AB84 -> 8300 | AC20: =AC84 -> 1 | AD20: 0 | AE20: -0.06 | AF20: 0.03
A21: Honda Civic EG6 | B21: 0.35 | C21: 1.217 | D21: -1.38 | E21: =C21+(-1*D21) -> 2.597 | F21: 1.48 | G21: 1.47 | H21: =AVERAGE(F21:G21) -> 1.475 | I21: 5 | J21: 0.5 | K21: 50 | L21: 0.3 | M21: 2 | N21: =L21*M21 -> 0.6 | O21: 0.29 | P21: 2 | Q21: =O21*P21 -> 0.58 | R21: 0.28 | S21: 2 | T21: =R21*S21 -> 0.56 | U21: 0 | V21: 0.34 | W21: 2.1 | X21: 122 | Y21: 140 | Z21: NA | AA21: 7300 | AB21: 7800 | AC21: 1 | AD21: 0 | AE21: -0.05 | AF21: 0.05
A22: Mazda MX-5 NA with roof | B22: 0.445 | C22: 1.178 | D22: -1.095 | E22: =C22+(-1*D22) -> 2.273 | F22: 1.416 | G22: 1.432 | H22: =AVERAGE(F22:G22) -> 1.424 | I22: 5 | J22: 0.5 | K22: 50 | L22: 0.3 | M22: 2 | N22: =L22*M22 -> 0.6 | O22: 0.29 | P22: 2 | Q22: =O22*P22 -> 0.58 | R22: 0.28 | S22: 2 | T22: =R22*S22 -> 0.56 | U22: 0 | V22: 0.41 | W22: 1.115 | X22: 127 | Y22: 155 | Z22: NA | AA22: 7000 | AB22: 7200 | AC22: 1 | AD22: 0 | AE22: -0.045 | AF22: 0.08
A23: Datsun 620 | B23: 0.39 | C23: 1.29 | D23: -1.27 | E23: =C23+(-1*D23) -> 2.56 | F23: 1.38 | G23: 1.38 | H23: =AVERAGE(F23:G23) -> 1.38 | I23: 5 | J23: 0.5 | K23: 50 | L23: 0.3 | M23: 2 | N23: =L23*M23 -> 0.6 | O23: 0.29 | P23: 2 | Q23: =O23*P23 -> 0.58 | R23: 0.28 | S23: 2 | T23: =R23*S23 -> 0.56 | U23: 0 | V23: 0.45 | W23: 1.262 | X23: 138 | Y23: 160 | Z23: 0.45 | AA23: 7000 | AB23: 6200 | AC23: 1 | AD23: 0 | AE23: -0.04 | AF23: 0.1
A24: Mazda MX-5 NA roof removed | B24: 0.445 | C24: 1.178 | D24: -1.095 | E24: =C24+(-1*D24) -> 2.273 | F24: 1.416 | G24: 1.432 | H24: =AVERAGE(F24:G24) -> 1.424 | I24: 5 | J24: 0.5 | K24: 50 | L24: 0.3 | M24: 2 | N24: =L24*M24 -> 0.6 | O24: 0.29 | P24: 2 | Q24: =O24*P24 -> 0.58 | R24: 0.28 | S24: 2 | T24: =R24*S24 -> 0.56 | U24: 0 | V24: 0.38 | W24: 1.115 | X24: 131 | Y24: 155 | Z24: NA | AA24: 7000 | AB24: 7200 | AC24: 1 | AD24: 0 | AE24: -0.045 | AF24: 0.08
A25: Pontiac Firebird Trans Am 1977 | B25: 0.4 | C25: 1.58 | D25: -1.18 | E25: =C25+(-1*D25) -> 2.76 | F25: 1.53 | G25: 1.53 | H25: =AVERAGE(F25:G25) -> 1.53 | I25: 4 | J25: 0.5 | K25: 50 | L25: 0.3 | M25: 2 | N25: =L25*M25 -> 0.6 | O25: 0.29 | P25: 2 | Q25: =O25*P25 -> 0.58 | R25: 0.28 | S25: 2 | T25: =R25*S25 -> 0.56 | U25: 0 | V25: 0.532 | W25: 1.532 | X25: 203 | Y25: 270 | Z25: NA | AA25: 7000 | AB25: 5000 | AC25: 1 | AD25: 0 | AE25: 0.14 | AF25: 0.43
A26: Mitsubishi Eclipse GS-T | B26: 0.45 | C26: 1.25 | D26: -1.28 | E26: =C26+(-1*D26) -> 2.53 | F26: 1.515 | G26: 1.508 | H26: =AVERAGE(F26:G26) -> 1.5115 | I26: 5 | J26: 0.5 | K26: 50 | L26: 0.3 | M26: 2 | N26: =L26*M26 -> 0.6 | O26: 0.29 | P26: 2 | Q26: =O26*P26 -> 0.58 | R26: 0.28 | S26: 2 | T26: =R26*S26 -> 0.56 | U26: 0 | V26: 0.512 | W26: 1.341 | X26: 174 | Y26: 185 | Z26: NA | AA26: 7000 | AB26: 6500 | AC26: 1 | AD26: 0 | AE26: -0.03 | AF26: 0.14
A27: Toyota Corolla AE86 | B27: 0.46 | C27: 1.279 | D27: -1.118 | E27: =C27+(-1*D27) -> 2.397 | F27: 1.38 | G27: 1.37 | H27: =AVERAGE(F27:G27) -> 1.375 | I27: 5 | J27: 0.5 | K27: 50 | L27: 0.3 | M27: 2 | N27: =L27*M27 -> 0.6 | O27: 0.29 | P27: 2 | Q27: =O27*P27 -> 0.58 | R27: 0.28 | S27: 2 | T27: =R27*S27 -> 0.56 | U27: 0 | V27: 0.445 | W27: 1.252 | X27: 132 | Y27: 154 | Z27: NA | AA27: 7000 | AB27: 7400 | AC27: 1 | AD27: 0 | AE27: -0.05 | AF27: 0.06
A28: Toyota MR-2 SW20 | B28: 0.35 | C28: 1.23 | D28: -1.22 | E28: =C28+(-1*D28) -> 2.45 | F28: 1.48 | G28: 1.47 | H28: =AVERAGE(F28:G28) -> 1.475 | I28: 5 | J28: 0.5 | K28: 50 | L28: 0.3 | M28: 2 | N28: =L28*M28 -> 0.6 | O28: 0.29 | P28: 2 | Q28: =O28*P28 -> 0.58 | R28: 0.28 | S28: 2 | T28: =R28*S28 -> 0.56 | U28: 0 | V28: 0.42 | W28: -1.253 | X28: 163 | Y28: 143 | Z28: NA | AA28: 7000 | AB28: 7000 | AC28: 1 | AD28: 0 | AE28: -0.04 | AF28: 0.1
A29: Mercedes-Benz 190 W201 | B29: 0.36 | C29: 1.24 | D29: -1.43 | E29: =C29+(-1*D29) -> 2.67 | F29: 1.42 | G29: 1.42 | H29: =AVERAGE(F29:G29) -> 1.42 | I29: 4 | J29: 0.3 | K29: 50 | L29: 0.3 | M29: 2 | N29: =L29*M29 -> 0.6 | O29: 0.29 | P29: 2 | Q29: =O29*P29 -> 0.58 | R29: 0.28 | S29: 2 | T29: =R29*S29 -> 0.56 | U29: 0 | V29: 0.46 | W29: 1.255 | X29: 165 | Y29: 170 | Z29: NA | AA29: 7000 | AB29: 6600 | AC29: 1 | AD29: 0 | AE29: -0.03 | AF29: 0.15
A30: Nissan Fairlady 240Z | B30: 0.26 | C30: 1.25 | D30: -1.12 | E30: =C30+(-1*D30) -> 2.37 | F30: 1.39 | G30: 1.38 | H30: =AVERAGE(F30:G30) -> 1.385 | I30: 5 | J30: 0.5 | K30: 50 | L30: 0.3 | M30: 2 | N30: =L30*M30 -> 0.6 | O30: 0.29 | P30: 2 | Q30: =O30*P30 -> 0.58 | R30: 0.28 | S30: 2 | T30: =R30*S30 -> 0.56 | U30: 0 | V30: 0.351 | W30: 1.291 | X30: 151 | Y30: 249 | Z30: 0.49 | AA30: 7000 | AB30: 7000 | AC30: 1 | AD30: 0 | AE30: 0.09 | AF30: 0.14
A31: BMW M3 E36 | B31: 0.28 | C31: 1.461 | D31: -1.233 | E31: =C31+(-1*D31) -> 2.694 | F31: 1.42 | G31: 1.439 | H31: =AVERAGE(F31:G31) -> 1.4295 | I31: 5 | J31: 0.5 | K31: 50 | L31: 0.3 | M31: 2 | N31: =L31*M31 -> 0.6 | O31: 0.29 | P31: 2 | Q31: =O31*P31 -> 0.58 | R31: 0.28 | S31: 2 | T31: =R31*S31 -> 0.56 | U31: 0 | V31: 0.337 | W31: 1.361 | X31: 193 | Y31: 180 | Z31: NA | AA31: 7000 | AB31: 6600 | AC31: 1 | AD31: 0 | AE31: 0.07 | AF31: 0.18
A32: Nissan Skyline 2000 GT-R | B32: 0.43 | C32: 1.47 | D32: -1.13 | E32: =C32+(-1*D32) -> 2.6 | F32: 1.5 | G32: 1.5 | H32: =AVERAGE(F32:G32) -> 1.5 | I32: 5 | J32: 0.3 | K32: 50 | L32: 0.3 | M32: 2 | N32: =L32*M32 -> 0.6 | O32: 0.29 | P32: 2 | Q32: =O32*P32 -> 0.58 | R32: 0.28 | S32: 2 | T32: =R32*S32 -> 0.56 | U32: 0 | V32: 0.566 | W32: 1.439 | X32: 160 | Y32: 199 | Z32: NA | AA32: 7000 | AB32: 7300 | AC32: 1 | AD32: 0 | AE32: 0.06 | AF32: 0.1
A33: Nissan 300ZX (Z32) | B33: 0.44 | C33: 1.28 | D33: -1.19 | E33: =C33+(-1*D33) -> 2.47 | F33: 1.495 | G33: 1.535 | H33: =AVERAGE(F33:G33) -> 1.515 | I33: 5 | J33: 0.5 | K33: 50 | L33: 0.3 | M33: 2 | N33: =L33*M33 -> 0.6 | O33: 0.29 | P33: 2 | Q33: =O33*P33 -> 0.58 | R33: 0.28 | S33: 2 | T33: =R33*S33 -> 0.56 | U33: 0 | V33: 0.385 | W33: 1.4 | X33: 221 | Y33: 220 | Z33: 0.62 | AA33: 7000 | AB33: 6800 | AC33: 1 | AD33: 0 | AE33: 0.1 | AF33: 0.2
A34: Nissan 180SX | B34: 0.319 | C34: 1.285 | D34: -1.2 | E34: =C34+(-1*D34) -> 2.485 | F34: 1.46 | G34: 1.46 | H34: =AVERAGE(F34:G34) -> 1.46 | I34: 5 | J34: 0.5 | K34: 50 | L34: 0.3 | M34: 2 | N34: =L34*M34 -> 0.6 | O34: 0.29 | P34: 2 | Q34: =O34*P34 -> 0.58 | R34: 0.28 | S34: 2 | T34: =R34*S34 -> 0.56 | U34: 0 | V34: 0.427 | W34: 1.35 | X34: 185 | Y34: 268 | Z34: 0.6 | AA34: 7000 | AB34: 7200 | AC34: 1 | AD34: 0 | AE34: -0.04 | AF34: 0.08
A35: Volkswagen Golf GTI Mk7 | B35: 0.43 | C35: 1.4 | D35: -1.3 | E35: =C35+(-1*D35) -> 2.7 | F35: 1.55 | G35: 1.54 | H35: =AVERAGE(F35:G35) -> 1.545 | I35: 6 | J35: 0.5 | K35: 50 | L35: 0.3 | M35: 2 | N35: =L35*M35 -> 0.6 | O35: 0.29 | P35: 2 | Q35: =O35*P35 -> 0.58 | R35: 0.28 | S35: 2 | T35: =R35*S35 -> 0.56 | U35: 0 | V35: 0.597 | W35: 1.621 | X35: 201 | Y35: 140 | Z35: 0.55 | AA35: 7000 | AB35: 6000 | AC35: 1 | AD35: 0 | AE35: -0.04 | AF35: 0.1
A36: Toyota GT86 | B36: 0.51 | C36: 1.099 | D36: -1.482 | E36: =C36+(-1*D36) -> 2.581 | F36: 1.52 | G36: 1.54 | H36: =AVERAGE(F36:G36) -> 1.53 | I36: 6 | J36: 0.5 | K36: 50 | L36: 0.3 | M36: 2 | N36: =L36*M36 -> 0.6 | O36: 0.29 | P36: 2 | Q36: =O36*P36 -> 0.58 | R36: 0.28 | S36: 2 | T36: =R36*S36 -> 0.56 | U36: 0 | V36: 0.548 | W36: 1.05 | X36: 198 | Y36: 200 | Z36: NA | AA36: 7000 | AB36: 7400 | AC36: 1 | AD36: 0 | AE36: 0.1 | AF36: 0.1
A37: Mini Cooper JCW F56 | B37: 0.42 | C37: 1.1 | D37: -1.34 | E37: =C37+(-1*D37) -> 2.44 | F37: 1.46 | G37: 1.45 | H37: =AVERAGE(F37:G37) -> 1.455 | I37: 6 | J37: 0.5 | K37: 50 | L37: 0.3 | M37: 2 | N37: =L37*M37 -> 0.6 | O37: 0.29 | P37: 2 | Q37: =O37*P37 -> 0.58 | R37: 0.28 | S37: 2 | T37: =R37*S37 -> 0.56 | U37: 0 | V37: 0.434 | W37: 1.097 | X37: 172 | Y37: 130 | Z37: 0.55 | AA37: 7000 | AB37: 6500 | AC37: 1 | AD37: 0 | AE37: -0.05 | AF37: 0.06
A38: Subaru Forester | B38: 0.46 | C38: 1.28 | D38: -1.255 | E38: =C38+(-1*D38) -> 2.535 | F38: 1.48 | G38: 1.48 | H38: =AVERAGE(F38:G38) -> 1.48 | I38: 5 | J38: 0.5 | K38: 50 | L38: 0.3 | M38: 2 | N38: =L38*M38 -> 0.6 | O38: 0.29 | P38: 2 | Q38: =O38*P38 -> 0.58 | R38: 0.28 | S38: 2 | T38: =R38*S38 -> 0.56 | U38: 0 | V38: 0.611 | W38: 1.412 | X38: 225 | Y38: 120 | Z38: 0.79 | AA38: 7000 | AB38: 6500 | AC38: 1 | AD38: 0 | AE38: 0.12 | AF38: 0.15
A39: Lada VAZ 2108 | B39: 0.37 | C39: 1.24 | D39: -1.21 | E39: =C39+(-1*D39) -> 2.45 | F39: 1.39 | G39: 1.39 | H39: =AVERAGE(F39:G39) -> 1.39 | I39: 4 | J39: 0.5 | K39: 50 | L39: 0.3 | M39: 2 | N39: =L39*M39 -> 0.6 | O39: 0.29 | P39: 2 | Q39: =O39*P39 -> 0.58 | R39: 0.28 | S39: 2 | T39: =R39*S39 -> 0.56 | U39: 0 | V39: 0.504 | W39: 1.315 | X39: 93 | Y39: 127 | Z39: NA | AA39: 7000 | AB39: 6000 | AC39: 1 | AD39: 0 | AE39: -0.05 | AF39: 0.05
A40: Volvo 240 | B40: 0.48 | C40: 1.546 | D40: -1.17 | E40: =C40+(-1*D40) -> 2.716 | F40: 1.35 | G40: 1.35 | H40: =AVERAGE(F40:G40) -> 1.35 | I40: 5 | J40: 0.3 | K40: 50 | L40: 0.3 | M40: 2 | N40: =L40*M40 -> 0.6 | O40: 0.29 | P40: 2 | Q40: =O40*P40 -> 0.58 | R40: 0.28 | S40: 2 | T40: =R40*S40 -> 0.56 | U40: 0 | V40: 0.558 | W40: 1.573 | X40: 119 | Y40: 140 | Z40: NA | AA40: 7000 | AB40: 6500 | AC40: 1 | AD40: 0 | AE40: -0.04 | AF40: 0.11
...
